2024-04-22 08:30:35,369 - DFI => Execução iniciada
2024-04-22 08:30:35,382 -     => Main - Execução iniciada
2024-04-22 08:30:35,382 -     => 'commodities' - Execução iniciada
2024-04-22 08:35:12,797 - DFI => Execução iniciada
2024-04-22 08:35:12,816 -     => Main - Execução iniciada
2024-04-22 08:35:12,817 -     => 'commodities' - Execução iniciada
2024-04-22 08:37:12,762 - DFI => Execução iniciada
2024-04-22 08:37:12,771 -     => Main - Execução iniciada
2024-04-22 08:37:12,772 -     => commodities - Execução iniciada
2024-04-22 08:37:12,773 -       => Error: Parâmetro encontrado com valor incorreto: Esse módulo aceita somente a origem [PostgreSQL]                                                                                                              
2024-04-22 08:40:30,862 - DFI => Execução iniciada
2024-04-22 08:41:23,368 - DFI => Execução iniciada
2024-04-22 08:42:38,325 - DFI => Execução iniciada
2024-04-22 08:55:19,639 - DFI => Execução iniciada
2024-04-22 08:56:18,274 - DFI => Execução iniciada
2024-04-22 08:56:23,244 - DFI => Execução iniciada
2024-04-22 08:56:31,021 - DFI => Execução iniciada
2024-04-22 08:56:31,046 -     => Main - Execução iniciada
2024-04-22 08:56:31,047 -     => commodities - Execução iniciada
2024-04-22 08:56:37,996 - DFI => Execução iniciada
2024-04-22 08:56:38,014 -     => Main - Execução iniciada
2024-04-22 08:56:38,015 -     => commodities - Execução iniciada
2024-04-22 08:56:54,269 -       => Error:       (X) connectDatabase.py.[connectDatabase]: Erro ao conectar ao database de Destino: : (pyodbc.OperationalError) ('08001', '[08001] [Microsoft][SQL Server Native Client 11.0]SQL Server Network Interfaces: Error Locating Server/Instance Specified [xFFFFFFFF].  (-1) (SQLDriverConnect); [08001] [Microsoft][SQL Server Native Client 11.0]Login timeout expired (0); [08001] [Microsoft][SQL Server Native Client 11.0]Invalid connection string attribute (0); [08001] [Microsoft][SQL Server Native Client 11.0]A network-related or instance-specific error has occurred while establishing a connection to SQL Server. Server is not found or not accessible. Check if instance name is correct and if SQL Server is configured to allow remote connections. For more information see SQL Server Books Online. (-1)')
(Background on this error at: https://sqlalche.me/e/20/e3q8)
2024-04-22 08:57:25,992 - DFI => Execução iniciada
2024-04-22 08:57:25,998 -     => Main - Execução iniciada
2024-04-22 08:57:25,998 -     => commodities - Execução iniciada
2024-04-22 08:57:41,897 -       => Error:       (X) connectDatabase.py.[connectDatabase]: Erro ao conectar ao database de Destino: : (pyodbc.OperationalError) ('08001', '[08001] [Microsoft][SQL Server Native Client 11.0]SQL Server Network Interfaces: Error Locating Server/Instance Specified [xFFFFFFFF].  (-1) (SQLDriverConnect); [08001] [Microsoft][SQL Server Native Client 11.0]Login timeout expired (0); [08001] [Microsoft][SQL Server Native Client 11.0]Invalid connection string attribute (0); [08001] [Microsoft][SQL Server Native Client 11.0]A network-related or instance-specific error has occurred while establishing a connection to SQL Server. Server is not found or not accessible. Check if instance name is correct and if SQL Server is configured to allow remote connections. For more information see SQL Server Books Online. (-1)')
(Background on this error at: https://sqlalche.me/e/20/e3q8)
2024-04-22 09:17:37,156 - DFI => Execução iniciada
2024-04-22 09:17:37,162 -     => Main - Execução iniciada
2024-04-22 09:17:37,163 -     => commodities - Execução iniciada
2024-04-22 09:17:53,219 -       => Error:       (X) connectDatabase.py.[connectDatabase]: Erro ao conectar ao database de Destino: : (pyodbc.OperationalError) ('08001', '[08001] [Microsoft][SQL Server Native Client 11.0]SQL Server Network Interfaces: Error Locating Server/Instance Specified [xFFFFFFFF].  (-1) (SQLDriverConnect); [08001] [Microsoft][SQL Server Native Client 11.0]Login timeout expired (0); [08001] [Microsoft][SQL Server Native Client 11.0]Invalid connection string attribute (0); [08001] [Microsoft][SQL Server Native Client 11.0]A network-related or instance-specific error has occurred while establishing a connection to SQL Server. Server is not found or not accessible. Check if instance name is correct and if SQL Server is configured to allow remote connections. For more information see SQL Server Books Online. (-1)')
(Background on this error at: https://sqlalche.me/e/20/e3q8)
2024-04-22 09:18:57,140 - DFI => Execução iniciada
2024-04-22 09:18:57,159 -     => Main - Execução iniciada
2024-04-22 09:18:57,160 -     => commodities - Execução iniciada
2024-04-22 09:19:55,308 -       => Error:       (X) connectDatabase.py.[connectDatabase]: Erro ao conectar ao database de Destino: : (pyodbc.OperationalError) ('08001', '[08001] [Microsoft][SQL Server Native Client 11.0]SQL Server Network Interfaces: Error Locating Server/Instance Specified [xFFFFFFFF].  (-1) (SQLDriverConnect); [08001] [Microsoft][SQL Server Native Client 11.0]Login timeout expired (0); [08001] [Microsoft][SQL Server Native Client 11.0]Invalid connection string attribute (0); [08001] [Microsoft][SQL Server Native Client 11.0]A network-related or instance-specific error has occurred while establishing a connection to SQL Server. Server is not found or not accessible. Check if instance name is correct and if SQL Server is configured to allow remote connections. For more information see SQL Server Books Online. (-1)')
(Background on this error at: https://sqlalche.me/e/20/e3q8)
2024-04-22 09:20:13,982 - DFI => Execução iniciada
2024-04-22 09:20:13,999 -     => Main - Execução iniciada
2024-04-22 09:20:14,000 -     => commodities - Execução iniciada
2024-04-22 09:22:38,527 -       => Error:       (X) connectDatabase.py.[connectDatabase]: Erro ao conectar ao database de Destino: : (pyodbc.OperationalError) ('08001', '[08001] [Microsoft][SQL Server Native Client 11.0]SQL Server Network Interfaces: Error Locating Server/Instance Specified [xFFFFFFFF].  (-1) (SQLDriverConnect); [08001] [Microsoft][SQL Server Native Client 11.0]Login timeout expired (0); [08001] [Microsoft][SQL Server Native Client 11.0]Invalid connection string attribute (0); [08001] [Microsoft][SQL Server Native Client 11.0]A network-related or instance-specific error has occurred while establishing a connection to SQL Server. Server is not found or not accessible. Check if instance name is correct and if SQL Server is configured to allow remote connections. For more information see SQL Server Books Online. (-1)')
(Background on this error at: https://sqlalche.me/e/20/e3q8)
2024-04-22 09:22:49,363 - DFI => Execução iniciada
2024-04-22 09:22:49,385 -     => Main - Execução iniciada
2024-04-22 09:22:49,387 -     => commodities - Execução iniciada
2024-04-22 09:23:07,523 - DFI => Execução iniciada
2024-04-22 09:23:07,541 -     => Main - Execução iniciada
2024-04-22 09:23:07,542 -     => commodities - Execução iniciada
2024-04-22 09:23:27,096 -       => Error:       (X) connectDatabase.py.[connectDatabase]: Erro ao conectar ao database de Destino: : (pyodbc.OperationalError) ('08001', '[08001] [Microsoft][SQL Server Native Client 11.0]SQL Server Network Interfaces: Error Locating Server/Instance Specified [xFFFFFFFF].  (-1) (SQLDriverConnect); [08001] [Microsoft][SQL Server Native Client 11.0]Login timeout expired (0); [08001] [Microsoft][SQL Server Native Client 11.0]Invalid connection string attribute (0); [08001] [Microsoft][SQL Server Native Client 11.0]A network-related or instance-specific error has occurred while establishing a connection to SQL Server. Server is not found or not accessible. Check if instance name is correct and if SQL Server is configured to allow remote connections. For more information see SQL Server Books Online. (-1)')
(Background on this error at: https://sqlalche.me/e/20/e3q8)
2024-04-22 09:24:39,570 - DFI => Execução iniciada
2024-04-22 09:24:39,594 -     => Main - Execução iniciada
2024-04-22 09:24:39,595 -     => commodities - Execução iniciada
2024-04-22 09:24:50,625 - DFI => Execução iniciada
2024-04-22 09:24:50,630 -     => Main - Execução iniciada
2024-04-22 09:24:50,631 -     => commodities - Execução iniciada
2024-04-22 09:25:22,222 - DFI => Execução iniciada
2024-04-22 09:25:22,240 -     => Main - Execução iniciada
2024-04-22 09:25:22,240 -     => commodities - Execução iniciada
2024-04-22 09:25:45,040 - DFI => Execução iniciada
2024-04-22 09:25:45,057 -     => Main - Execução iniciada
2024-04-22 09:25:45,058 -     => commodities - Execução iniciada
2024-04-22 09:29:33,034 - DFI => Execução iniciada
2024-04-22 09:29:33,043 -     => Main - Execução iniciada
2024-04-22 09:29:33,044 -     => commodities - Execução iniciada
2024-04-22 09:29:48,875 -       => Error:       (X) connectDatabase.py.[connectDatabase]: Erro ao conectar ao database de Destino: : (pyodbc.OperationalError) ('08001', '[08001] [Microsoft][SQL Server Native Client 11.0]SQL Server Network Interfaces: Error Locating Server/Instance Specified [xFFFFFFFF].  (-1) (SQLDriverConnect); [08001] [Microsoft][SQL Server Native Client 11.0]Login timeout expired (0); [08001] [Microsoft][SQL Server Native Client 11.0]Invalid connection string attribute (0); [08001] [Microsoft][SQL Server Native Client 11.0]A network-related or instance-specific error has occurred while establishing a connection to SQL Server. Server is not found or not accessible. Check if instance name is correct and if SQL Server is configured to allow remote connections. For more information see SQL Server Books Online. (-1)')
(Background on this error at: https://sqlalche.me/e/20/e3q8)
2024-04-22 09:30:04,041 - DFI => Execução iniciada
2024-04-22 09:30:04,050 -     => Main - Execução iniciada
2024-04-22 09:30:04,051 -     => commodities - Execução iniciada
2024-04-22 09:30:25,350 - DFI => Execução iniciada
2024-04-22 09:30:25,357 -     => Main - Execução iniciada
2024-04-22 09:30:25,357 -     => 'commodities' - Execução iniciada
2024-04-22 09:32:09,018 - DFI => Execução iniciada
2024-04-22 09:32:09,028 -     => Main - Execução iniciada
2024-04-22 09:32:09,028 -     => commodities - Execução iniciada
2024-04-22 09:32:22,219 - DFI => Execução iniciada
2024-04-22 09:32:22,228 -     => Main - Execução iniciada
2024-04-22 09:32:22,228 -     => commodities - Execução iniciada
2024-04-22 09:35:35,967 - DFI => Execução iniciada
2024-04-22 09:35:35,985 -     => Main - Execução iniciada
2024-04-22 09:35:35,987 -     => commodities - Execução iniciada
2024-04-22 09:37:07,029 - DFI => Execução iniciada
2024-04-22 09:37:07,046 -     => Main - Execução iniciada
2024-04-22 09:37:07,047 -     => commodities - Execução iniciada
2024-04-22 10:56:50,575 - DFI => Execução iniciada
2024-04-22 10:56:50,581 -     => Main - Execução iniciada
2024-04-22 10:56:50,581 -     => commodities - Execução iniciada
2024-04-22 10:56:50,582 -       => Error: Parâmetro encontrado com valor incorreto: Esse módulo aceita somente a origem [PostgreSQL]                                                                                                              
2024-04-22 10:58:35,464 - DFI => Execução iniciada
2024-04-22 10:58:35,470 -     => Main - Execução iniciada
2024-04-22 10:58:35,470 -     => commodities - Execução iniciada
2024-04-22 10:58:35,471 -       => Error: Parâmetro encontrado com valor incorreto: Esse módulo aceita somente a origem [PostgreSQL]                                                                                                              
2024-04-22 10:59:34,905 - DFI => Execução iniciada
2024-04-22 10:59:34,914 -     => Main - Execução iniciada
2024-04-22 10:59:34,914 -     => commodities - Execução iniciada
2024-04-22 10:59:34,915 -       => Error: Parâmetro encontrado com valor incorreto: Esse módulo aceita somente a origem [Excel]                                                                                                                   
2024-04-22 10:59:50,375 - DFI => Execução iniciada
2024-04-22 10:59:50,397 -     => Main - Execução iniciada
2024-04-22 10:59:50,398 -     => commodities - Execução iniciada
2024-04-22 11:02:36,549 - DFI => Execução iniciada
2024-04-22 11:09:08,951 - DFI => Execução iniciada
2024-04-22 11:13:33,784 - DFI => Execução iniciada
2024-04-22 11:15:52,717 - DFI => Execução iniciada
2024-04-22 11:16:29,782 - DFI => Execução iniciada
2024-04-22 11:26:59,007 - DFI => Execução iniciada
2024-04-22 11:29:44,948 - DFI => Execução iniciada
2024-04-22 11:44:01,742 - DFI => Execução iniciada
2024-04-22 12:04:48,321 - DFI => Execução iniciada
2024-04-22 12:07:15,925 - DFI => Execução iniciada
2024-04-22 12:07:15,946 -     => Main - Execução iniciada
2024-04-22 12:07:15,947 -     => commodities - Execução iniciada
2024-04-22 12:07:31,077 -       => Error:       (X) connectDatabase.py.[connectDatabase]: Erro ao conectar ao database de Destino: : (pyodbc.ProgrammingError) ('42000', "[42000] [Microsoft][SQL Server Native Client 11.0][SQL Server]Sintaxe incorreta próxima a 'MRV_Commodity_History'. (102) (SQLExecDirectW)")
[SQL: SELECT COUNT(*) FROM INFORMATION_SCHEMA.TABLES WHERE TABLE_NAME = ''MRV_Commodity_History'']
(Background on this error at: https://sqlalche.me/e/20/f405)
2024-04-22 12:08:16,317 - DFI => Execução iniciada
2024-04-22 12:08:16,339 -     => Main - Execução iniciada
2024-04-22 12:08:16,340 -     => commodities - Execução iniciada
2024-04-22 12:11:46,643 - DFI => Execução iniciada
2024-04-22 12:16:06,530 - DFI => Execução iniciada
2024-04-22 12:16:06,540 -     => Main - Execução iniciada
2024-04-22 12:16:06,541 -     => commodities - Execução iniciada
2024-04-22 12:16:06,740 -       => Error:       (X) connectDatabase.py.[connectDatabase]: Erro ao conectar ao database de Destino: : (pyodbc.ProgrammingError) ('42000', "[42000] [Microsoft][SQL Server Native Client 11.0][SQL Server]Sintaxe incorreta próxima a 'MRV_Commodity_History'. (102) (SQLExecDirectW)")
[SQL: SELECT COUNT(*) FROM INFORMATION_SCHEMA.TABLES WHERE TABLE_NAME = ''MRV_Commodity_History'']
(Background on this error at: https://sqlalche.me/e/20/f405)
2024-04-22 12:16:18,454 - DFI => Execução iniciada
2024-04-22 12:21:56,479 - DFI => Execução iniciada
2024-04-22 12:24:09,320 - DFI => Execução iniciada
2024-04-22 12:24:09,327 -     => Main - Execução iniciada
2024-04-22 12:24:09,327 -     => commodities - Execução iniciada
2024-04-22 12:24:10,435 -       => Error:       (X) tools.py.[verifyFile]: O arquivo serie_mandioca.xls não foi encontrado no caminho D:\\Development\\Python\\dfi\\arquivos\\serie-historica\\.: 
2024-04-22 12:24:10,436 -       => Error:       (X) tools.py.[verifyFile]: O arquivo serie_milho.xls não foi encontrado no caminho D:\\Development\\Python\\dfi\\arquivos\\serie-historica\\.: 
2024-04-22 12:24:10,437 -       => Error:       (X) tools.py.[verifyFile]: O arquivo serie_ovo.xls não foi encontrado no caminho D:\\Development\\Python\\dfi\\arquivos\\serie-historica\\.: 
2024-04-22 12:24:10,438 -       => Error:       (X) tools.py.[verifyFile]: O arquivo serie_soja.xls não foi encontrado no caminho D:\\Development\\Python\\dfi\\arquivos\\serie-historica\\.: 
2024-04-22 12:24:10,439 -       => Error:       (X) tools.py.[verifyFile]: O arquivo serie_trigo.xls não foi encontrado no caminho D:\\Development\\Python\\dfi\\arquivos\\serie-historica\\.: 
2024-04-22 12:26:55,385 - DFI => Execução iniciada
2024-04-22 12:26:55,391 -     => Main - Execução iniciada
2024-04-22 12:26:55,392 -     => commodities - Execução iniciada
2024-04-22 12:26:56,178 -       => Error:       (X) tools.py.[verifyFile]: O arquivo serie_mandioca.xls não foi encontrado no caminho D:\Development\Python\dfi\arquivos\serie-historica\.: 
2024-04-22 12:26:56,179 -       => Error:       (X) tools.py.[verifyFile]: O arquivo serie_milho.xls não foi encontrado no caminho D:\Development\Python\dfi\arquivos\\serie-historica\.: 
2024-04-22 12:26:56,180 -       => Error:       (X) tools.py.[verifyFile]: O arquivo serie_ovo.xls não foi encontrado no caminho D:\Development\Python\\dfi\arquivos\serie-historica\.: 
2024-04-22 12:26:56,181 -       => Error:       (X) tools.py.[verifyFile]: O arquivo serie_soja.xls não foi encontrado no caminho D:\Development\Python\\dfi\arquivos\serie-historica\.: 
2024-04-22 12:26:56,182 -       => Error:       (X) tools.py.[verifyFile]: O arquivo serie_trigo.xls não foi encontrado no caminho D:\Development\Python\dfi\arquivos\serie-historica\.: 
2024-04-22 12:28:45,980 - DFI => Execução iniciada
2024-04-22 12:28:45,987 -     => Main - Execução iniciada
2024-04-22 12:28:45,987 -     => commodities - Execução iniciada
2024-04-22 12:28:46,782 -       => Error:       (X) tools.py.[verifyFile]: O arquivo serie_acucar.xls não foi encontrado no caminho D:\Development\Python\dfi\arquivos\serie-historica\.: 
2024-04-22 12:28:46,783 -       => Error:       (X) tools.py.[verifyFile]: O arquivo serie_leite.xls não foi encontrado no caminho D:\Development\Python\dfi\arquivos\serie-historica\.: 
2024-04-22 12:28:46,784 -       => Error:       (X) tools.py.[verifyFile]: O arquivo serie_mandioca.xls não foi encontrado no caminho D:\Development\Python\dfi\arquivos\serie-historica\.: 
2024-04-22 12:28:46,785 -       => Error:       (X) tools.py.[verifyFile]: O arquivo serie_milho.xls não foi encontrado no caminho D:\Development\Python\dfi\arquivos\\serie-historica\.: 
2024-04-22 12:28:46,786 -       => Error:       (X) tools.py.[verifyFile]: O arquivo serie_ovo.xls não foi encontrado no caminho D:\Development\Python\\dfi\arquivos\serie-historica\.: 
2024-04-22 12:28:46,787 -       => Error:       (X) tools.py.[verifyFile]: O arquivo serie_soja.xls não foi encontrado no caminho D:\Development\Python\\dfi\arquivos\serie-historica\.: 
2024-04-22 12:28:46,788 -       => Error:       (X) tools.py.[verifyFile]: O arquivo serie_trigo.xls não foi encontrado no caminho D:\Development\Python\dfi\arquivos\serie-historica\.: 
2024-04-22 12:30:49,996 -       => Error:       (X) importXlsToDataframe.py.[executeImportXlsToDataframe]: Erro durante a importação de dados:: 'str' object has no attribute 'append'
2024-04-22 13:40:05,507 - DFI => Execução iniciada
2024-04-22 13:40:05,517 -     => Main - Execução iniciada
2024-04-22 13:40:05,517 -     => commodities - Execução iniciada
2024-04-22 13:42:21,833 -       => Error:       (X) importXlsToDataframe.py.[executeImportXlsToDataframe]: Erro durante a importação de dados:: 'str' object has no attribute 'append'
2024-04-22 13:42:49,525 - DFI => Execução iniciada
2024-04-22 13:42:49,533 -     => Main - Execução iniciada
2024-04-22 13:42:49,533 -     => commodities - Execução iniciada
2024-04-22 13:42:50,331 -       => Error:       (X) importXlsToDataframe.py.[executeImportXlsToDataframe]: Erro durante a importação de dados:: 'str' object has no attribute 'append'
2024-04-22 13:43:03,254 - DFI => Execução iniciada
2024-04-22 13:43:09,193 -     => Main - Execução iniciada
2024-04-22 13:43:09,195 -     => commodities - Execução iniciada
2024-04-22 13:46:07,541 -       => Error:       (X) importXlsToDataframe.py.[executeImportXlsToDataframe]: Erro durante a importação de dados:: 'str' object has no attribute 'append'
2024-04-22 13:46:15,114 - DFI => Execução iniciada
2024-04-22 13:46:15,135 -     => Main - Execução iniciada
2024-04-22 13:46:15,136 -     => commodities - Execução iniciada
2024-04-22 13:48:02,988 -       => Error:       (X) importXlsToDataframe.py.[executeImportXlsToDataframe]: Erro durante a importação de dados:: 'str' object has no attribute 'append'
2024-04-22 13:48:12,020 - DFI => Execução iniciada
2024-04-22 13:48:12,041 -     => Main - Execução iniciada
2024-04-22 13:48:12,042 -     => commodities - Execução iniciada
2024-04-22 13:55:01,032 - DFI => Execução iniciada
2024-04-22 13:55:01,053 -     => Main - Execução iniciada
2024-04-22 13:55:01,054 -     => commodities - Execução iniciada
2024-04-22 13:56:07,514 - DFI => Execução iniciada
2024-04-22 14:05:00,643 - DFI => Execução iniciada
2024-04-22 14:05:00,649 -     => Main - Execução iniciada
2024-04-22 14:05:00,649 -     => commodities - Execução iniciada
2024-04-22 14:05:24,349 - DFI => Execução iniciada
2024-04-22 14:05:24,360 -     => Main - Execução iniciada
2024-04-22 14:05:24,361 -     => commodities - Execução iniciada
2024-04-22 14:05:25,375 -       => Error:       (X) importXlsToDataframe.py.[executeImportXlsToDataframe]: Erro durante a importação de dados:: unsupported operand type(s) for -: 'str' and 'int'
2024-04-22 14:10:15,680 - DFI => Execução iniciada
2024-04-22 14:10:32,441 - DFI => Execução iniciada
2024-04-22 14:12:02,878 - DFI => Execução iniciada
2024-04-22 14:12:05,074 -     => Main - Execução iniciada
2024-04-22 14:12:05,075 -     => commodities - Execução iniciada
2024-04-22 14:19:06,469 - DFI => Execução iniciada
2024-04-22 14:27:06,518 - DFI => Execução iniciada
2024-04-22 14:29:21,577 - DFI => Execução iniciada
2024-04-22 14:35:33,618 - DFI => Execução iniciada
2024-04-22 14:36:31,375 - DFI => Execução iniciada
2024-04-22 14:38:24,551 - DFI => Execução iniciada
2024-04-22 14:45:09,328 - DFI => Execução iniciada
2024-04-22 14:48:22,504 - DFI => Execução iniciada
2024-04-22 14:55:26,238 - DFI => Execução iniciada
2024-04-22 14:57:20,120 - DFI => Execução iniciada
2024-04-22 14:58:14,689 - DFI => Execução iniciada
2024-04-22 14:58:14,697 -     => Main - Execução iniciada
2024-04-22 14:58:14,697 -     => commodities - Execução iniciada
2024-04-22 14:58:44,231 - DFI => Execução iniciada
2024-04-22 15:03:08,440 - DFI => Execução iniciada
2024-04-22 15:03:08,446 -     => Main - Execução iniciada
2024-04-22 15:03:08,447 -     => commodities - Execução iniciada
2024-04-22 15:03:09,886 -       => Error:       (X) importXlsToDataframe.py.[importXlsSeriesToDataframe]: Erro ao importar informações dos arquivos em série:: can only concatenate str (not "KeyError") to str
2024-04-22 15:03:32,189 - DFI => Execução iniciada
2024-04-22 15:04:08,687 -     => Main - Execução iniciada
2024-04-22 15:04:08,688 -     => commodities - Execução iniciada
2024-04-22 15:04:10,522 -       => Error:       (X) importXlsToDataframe.py.[importXlsSeriesToDataframe]: Erro ao importar informações dos arquivos em série:: can only concatenate str (not "KeyError") to str
2024-04-22 15:04:53,297 - DFI => Execução iniciada
2024-04-22 15:04:53,320 -     => Main - Execução iniciada
2024-04-22 15:04:53,321 -     => commodities - Execução iniciada
2024-04-22 15:04:54,225 -       => Error:       (X) importXlsToDataframe.py.[importXlsSeriesToDataframe]: Erro ao importar informações dos arquivos em série:: can only concatenate str (not "KeyError") to str
2024-04-22 15:05:20,108 - DFI => Execução iniciada
2024-04-22 15:05:20,129 -     => Main - Execução iniciada
2024-04-22 15:05:20,130 -     => commodities - Execução iniciada
2024-04-22 16:00:38,833 -       => Error:       (X) importXlsToDataframe.py.[importXlsSeriesToDataframe]: Erro ao importar informações dos arquivos em série:: can only concatenate str (not "KeyError") to str
2024-04-22 16:00:56,537 - DFI => Execução iniciada
2024-04-22 16:00:56,568 -     => Main - Execução iniciada
2024-04-22 16:00:56,570 -     => commodities - Execução iniciada
2024-04-22 16:12:52,100 - DFI => Execução iniciada
2024-04-22 16:12:52,122 -     => Main - Execução iniciada
2024-04-22 16:12:52,122 -     => commodities - Execução iniciada
2024-04-22 16:13:12,196 -       => Error:       (X) importXlsToDataframe.py.[importXlsSeriesToDataframe]: Erro ao importar informações dos arquivos em série:: can only concatenate str (not "KeyError") to str
2024-04-22 16:15:03,703 - DFI => Execução iniciada
2024-04-22 16:15:03,709 -     => Main - Execução iniciada
2024-04-22 16:15:03,709 -     => commodities - Execução iniciada
2024-04-22 16:15:04,518 -       => Error:       (X) importXlsToDataframe.py.[importXlsSeriesToDataframe]: Erro ao importar informações dos arquivos em série:: can only concatenate str (not "KeyError") to str
2024-04-22 16:15:20,258 - DFI => Execução iniciada
2024-04-22 16:15:20,279 -     => Main - Execução iniciada
2024-04-22 16:15:20,280 -     => commodities - Execução iniciada
2024-04-22 16:16:45,414 - DFI => Execução iniciada
2024-04-22 16:16:45,434 -     => Main - Execução iniciada
2024-04-22 16:16:45,435 -     => commodities - Execução iniciada
2024-04-22 16:17:07,533 - DFI => Execução iniciada
2024-04-22 16:17:47,173 - DFI => Execução iniciada
2024-04-22 16:17:47,180 -     => Main - Execução iniciada
2024-04-22 16:17:47,180 -     => commodities - Execução iniciada
2024-04-22 16:17:47,976 -       => Error:       (X) importXlsToDataframe.py.[importXlsSeriesToDataframe]: Erro ao importar informações dos arquivos em série:: can only concatenate str (not "KeyError") to str
2024-04-22 16:17:55,257 - DFI => Execução iniciada
2024-04-22 16:18:42,042 - DFI => Execução iniciada
2024-04-22 16:21:28,657 - DFI => Execução iniciada
2024-04-22 16:22:47,099 -     => Main - Execução iniciada
2024-04-22 16:22:47,100 -     => commodities - Execução iniciada
2024-04-22 16:23:03,416 -       => Error:       (X) importXlsToDataframe.py.[executeImportXlsToDataframe]: Erro durante a importação de dados:: unsupported operand type(s) for -: 'str' and 'int'
2024-04-22 16:23:46,193 - DFI => Execução iniciada
2024-04-22 16:23:46,211 -     => Main - Execução iniciada
2024-04-22 16:23:46,212 -     => commodities - Execução iniciada
2024-04-22 16:26:28,175 -       => Error:       (X) importXlsToDataframe.py.[executeImportXlsToDataframe]: Erro durante a importação de dados:: unsupported operand type(s) for -: 'str' and 'int'
2024-04-22 16:26:34,546 - DFI => Execução iniciada
2024-04-22 16:26:34,565 -     => Main - Execução iniciada
2024-04-22 16:26:34,566 -     => commodities - Execução iniciada
2024-04-22 16:28:03,462 -       => Error:       (X) importXlsToDataframe.py.[executeImportXlsToDataframe]: Erro durante a importação de dados:: unsupported operand type(s) for -: 'str' and 'int'
2024-04-22 16:28:32,942 - DFI => Execução iniciada
2024-04-22 16:31:17,939 - DFI => Execução iniciada
2024-04-22 16:31:34,947 -     => Main - Execução iniciada
2024-04-22 16:31:34,948 -     => commodities - Execução iniciada
2024-04-22 16:31:41,672 -       => Error:       (X) importXlsToDataframe.py.[executeImportXlsToDataframe]: Erro durante a importação de dados:: Worksheet named 'Plan1' not found
2024-04-22 16:36:30,425 - DFI => Execução iniciada
2024-04-22 16:36:52,168 - DFI => Execução iniciada
2024-04-22 16:38:11,740 - DFI => Execução iniciada
2024-04-22 16:38:11,747 -     => Main - Execução iniciada
2024-04-22 16:38:11,747 -     => commodities - Execução iniciada
2024-04-22 16:38:12,782 -       => Error:       (X) importXlsToDataframe.py.[executeImportXlsToDataframe]: Erro durante a importação de dados:: Invalid column name: [Data
2024-04-22 16:38:52,411 - DFI => Execução iniciada
2024-04-22 16:40:32,727 - DFI => Execução iniciada
2024-04-22 16:42:38,070 - DFI => Execução iniciada
2024-04-22 16:48:00,057 - DFI => Execução iniciada
2024-04-22 16:50:16,213 - DFI => Execução iniciada
2024-04-22 17:18:02,688 - DFI => Execução iniciada
2024-04-22 17:22:44,560 - DFI => Execução iniciada
2024-04-22 17:23:11,499 - DFI => Execução iniciada
2024-04-22 17:25:25,262 - DFI => Execução iniciada
2024-04-22 17:28:57,565 - DFI => Execução iniciada
2024-04-22 17:30:11,396 - DFI => Execução iniciada
2024-04-22 17:31:25,014 - DFI => Execução iniciada
2024-04-22 17:35:16,583 - DFI => Execução iniciada
2024-04-22 17:38:53,787 - DFI => Execução iniciada
2024-04-22 17:40:28,993 - DFI => Execução iniciada
2024-04-22 17:42:11,740 - DFI => Execução iniciada
2024-04-22 17:43:09,177 - DFI => Execução iniciada
2024-04-22 17:44:35,607 - DFI => Execução iniciada
2024-04-22 17:49:39,538 - DFI => Execução iniciada
2024-04-22 17:50:43,792 - DFI => Execução iniciada
2024-04-22 17:51:58,080 -     => Main - Execução iniciada
2024-04-22 17:51:58,081 -     => commodities - Execução iniciada
2024-04-22 17:52:09,353 -       => Error:       (X) importXlsToDataframe.py.[executeImportXlsToDataframe]: Erro durante a importação de dados:: Usecols do not match columns, columns expected but not found: [' À vista R$'] (sheet: Plan 1)
2024-04-22 17:53:06,835 - DFI => Execução iniciada
2024-04-22 17:54:18,728 - DFI => Execução iniciada
2024-04-22 17:55:14,433 - DFI => Execução iniciada
2024-04-22 17:57:43,690 - DFI => Execução iniciada
2024-04-22 18:00:17,757 - DFI => Execução iniciada
2024-04-22 18:03:43,963 - DFI => Execução iniciada
2024-04-22 18:05:55,891 - DFI => Execução iniciada
2024-04-22 18:05:55,898 -     => Main - Execução iniciada
2024-04-22 18:05:55,898 -     => commodities - Execução iniciada
2024-04-22 18:06:27,504 - DFI => Execução iniciada
2024-04-22 18:07:04,025 - DFI => Execução iniciada
2024-04-22 18:07:25,577 -     => Main - Execução iniciada
2024-04-22 18:07:25,579 -     => commodities - Execução iniciada
2024-04-22 18:07:58,824 -       => Error:       (X) importXlsToDataframe.py.[executeImportXlsToDataframe]: Erro durante a importação de dados:: strptime() argument 1 must be str, not datetime.date
2024-04-22 18:09:10,022 - DFI => Execução iniciada
2024-04-22 18:09:10,028 -     => Main - Execução iniciada
2024-04-22 18:09:10,028 -     => commodities - Execução iniciada
2024-04-22 18:09:11,613 -       => Error:       (X) importXlsToDataframe.py.[executeImportXlsToDataframe]: Erro durante a importação de dados:: unsupported operand type(s) for -: 'str' and 'int'
