2024-05-21 12:01:29,132 - DFI => Execução iniciada
2024-05-21 12:01:29,145 -     => Main - Execução iniciada
2024-05-21 12:01:29,145 -     => avacorp - Execução iniciada
2024-05-21 12:01:30,891 -       => Error:       (X) importDatabaseToDataframe.py.[executeImportDatabaseToDataframe]: Erro durante a importação de dados:: 
2024-05-21 12:02:18,880 - DFI => Execução iniciada
2024-05-21 12:02:18,889 -     => Main - Execução iniciada
2024-05-21 12:02:18,889 -     => avacorp - Execução iniciada
2024-05-21 12:02:20,334 -       => Error:       (X) importDatabaseToDataframe.py.[executeImportDatabaseToDataframe]: Erro durante a importação de dados:: Unable to allocate 461. KiB for an array with shape (9, 6562) and data type float64
2024-05-21 12:07:41,138 - DFI => Execução iniciada
2024-05-21 12:07:41,147 -     => Main - Execução iniciada
2024-05-21 12:07:41,147 -     => avacorp - Execução iniciada
2024-05-21 12:07:43,293 -       => Error:       (X) importDatabaseToDataframe.py.[executeImportDatabaseToDataframe]: Erro durante a importação de dados:: Index(...) must be called with a collection of some kind, '' was passed
2024-05-21 12:10:28,708 - DFI => Execução iniciada
2024-05-21 12:10:28,734 -     => Main - Execução iniciada
2024-05-21 12:10:28,735 -     => avacorp - Execução iniciada
2024-05-21 12:10:30,884 -       => Error:       (X) importDatabaseToDataframe.py.[executeImportDatabaseToDataframe]: Erro durante a importação de dados:: Index(...) must be called with a collection of some kind, '' was passed
2024-05-21 13:34:54,036 - DFI => Execução iniciada
2024-05-21 13:34:54,069 -     => Main - Execução iniciada
2024-05-21 13:34:54,072 -     => avacorp - Execução iniciada
2024-05-21 13:35:00,558 -       => Error:       (X) connectDatabase.py.[connectDatabase]: Conexão com Origem: Server:Database:[168.75.71.21:dftransportes]:: 'DatabaseSourceInfo' object has no attribute 'get_addressDestiny'
2024-05-21 13:37:51,642 - DFI => Execução iniciada
2024-05-21 13:37:51,683 -     => Main - Execução iniciada
2024-05-21 13:37:51,684 -     => avacorp - Execução iniciada
2024-05-21 13:38:16,373 -       => Error:       (X) connectDatabase.py.[connectDatabase]: Conexão com Origem: Server:Database:[168.75.71.21:dftransportes]:: 'DatabaseSourceInfo' object has no attribute 'get_addressDestiny'
2024-05-21 13:38:36,373 - DFI => Execução iniciada
2024-05-21 13:38:36,401 -     => Main - Execução iniciada
2024-05-21 13:38:36,402 -     => avacorp - Execução iniciada
2024-05-21 13:40:19,005 -       => Error:       (X) connectDatabase.py.[connectDatabase]: Conexão com Origem: Server:Database:[168.75.71.21:dftransportes]:: 'DatabaseSourceInfo' object has no attribute 'get_addressDestiny'
2024-05-21 13:40:42,985 - DFI => Execução iniciada
2024-05-21 13:40:43,017 -     => Main - Execução iniciada
2024-05-21 13:40:43,018 -     => avacorp - Execução iniciada
2024-05-21 13:41:40,783 - DFI => Execução iniciada
2024-05-21 13:41:40,792 -     => Main - Execução iniciada
2024-05-21 13:41:40,793 -     => avacorp - Execução iniciada
2024-05-21 13:43:26,067 -     => avacorp - Execução concluída
2024-05-21 13:43:26,081 -     => Main - Execução concluída
2024-05-21 13:45:26,159 -     => Main - Execução iniciada
2024-05-21 13:45:26,159 -     => avacorp - Execução iniciada
2024-05-21 13:46:46,083 -     => avacorp - Execução concluída
2024-05-21 13:46:46,098 -     => Main - Execução concluída
2024-05-21 13:48:46,174 -     => Main - Execução iniciada
2024-05-21 13:48:46,174 -     => avacorp - Execução iniciada
2024-05-21 13:49:38,644 -       => Error:       (X) exportDataframeToDatabase.py.[exportDataframeToDatabase]: Erro ao exportar informações para o(s) database(s) de Destino:: Can't reconnect until invalid transaction is rolled back.  Please rollback() fully before proceeding (Background on this error at: https://sqlalche.me/e/20/8s2b)
